package com.ishostak.tasks.habrexceptionscode;

public class App {
    public static void main(String[] args) {
        System.err.println("#1.in");
        try {
            f(); // создаем фрейм, помещаем в стек, передаем в него управление
        } catch (Error e) { // "перехватили" "летящее" исключение
            System.err.println("#1.CATCH");  // и работаем
        }
        System.err.println("#1.out");  // работаем дальше
    }

    public static void f() {
        System.err.println(".   #2.in");
        g(); // создаем фрейм, помещаем в стек, передаем в него управление
        System.err.println(".   #2.out"); // ПРОПУСТИЛИ!
    }

    public static void g() {
        System.err.println(".   .   #3.in");
        h(); // создаем фрейм, помещаем в стек, передаем в него управление
        System.err.println(".   .   #3.out"); // ПРОПУСТИЛИ!
    }

    public static void h() {
        System.err.println(".   .   .   #4.in");
        if (true) {
            System.err.println(".   .   .   #4.THROW");
            throw new Error(); // выходим со всей пачки фреймов ("раскрутка стека") по 'throw'
        }
        System.err.println(".   .   .   #4.out"); // ПРОПУСТИЛИ!
    }


    public static void main2(String[] args) {
        try {
            System.err.print(" 0");
            if (true) {throw new RuntimeException();}
            System.err.print(" 1");
        } catch (RuntimeException e) {     // перехватили RuntimeException
            System.err.print(" 2");
            if (true) {throw new Error();} // и бросили новый Error
        } catch (Error e) { // хотя есть cath по Error "ниже", но мы в него не попадаем
            System.err.print(" 3");
        }
        System.err.println(" 4");
    }

    public static void main3(String[] args) {
        try {
            System.err.print(" 0");
            if (true) {throw new RuntimeException();}
            System.err.print(" 1");
        } catch (RuntimeException e) { // перехватили RuntimeException
            System.err.print(" 2.1");
            try {
                System.err.print(" 2.2");
                if (true) {throw new Error();} // и бросили новый Error
                System.err.print(" 2.3");
            } catch (Throwable t) {            // перехватили Error
                System.err.print(" 2.4");
            }
            System.err.print(" 2.5");
        } catch (Error e) { // хотя есть cath по Error "ниже", но мы в него не попадаем
            System.err.print(" 3");
        }
        System.err.println(" 4");
    }

    public static void mai4(String[] args) {
        try {
            System.err.println("try");
            if (true) {throw new RuntimeException();}
        } finally {
            System.err.println("finally");
        }
        System.err.println("more");
    /*
        >> try
         >> finally
        >> Exception in thread "main" java.lang.RuntimeException
     */
    }

    public static void main5(String[] args) {
        try {
            System.err.print(" 0");
            try {
                System.err.print(" 1");
                if (true) {throw new RuntimeException();}
                System.err.print(" 2");
            } catch (RuntimeException e) {
                System.err.print(" 3"); // ЗАХОДИМ - есть исключение
            } finally {
                System.err.print(" 4"); // заходим всегда
            }
            System.err.print(" 5");     // заходим - выполнение УЖЕ в норме
        } catch (Exception e) {
            System.err.print(" 6");     // не заходим - нет исключения, УЖЕ перехвачено
        } finally {
            System.err.print(" 7");     // заходим всегда
        }
        System.err.print(" 8");         // заходим - выполнение УЖЕ в норме

        // 0 1 3 4 5 7 8
    }

}